2018-06-25 20:33:15.883802: I tensorflow/core/platform/cpu_feature_guard.cc:140] Your CPU supports instructions that this TensorFlow binary was not compiled to use: AVX2 FMA
2018-06-25 20:33:16.002304: I tensorflow/stream_executor/cuda/cuda_gpu_executor.cc:898] successful NUMA node read from SysFS had negative value (-1), but there must be at least one NUMA node, so returning NUMA node zero
2018-06-25 20:33:16.002678: I tensorflow/core/common_runtime/gpu/gpu_device.cc:1212] Found device 0 with properties: 
name: GeForce GTX 1080 Ti major: 6 minor: 1 memoryClockRate(GHz): 1.6325
pciBusID: 0000:01:00.0
totalMemory: 10.91GiB freeMemory: 10.69GiB
2018-06-25 20:33:16.098766: I tensorflow/stream_executor/cuda/cuda_gpu_executor.cc:898] successful NUMA node read from SysFS had negative value (-1), but there must be at least one NUMA node, so returning NUMA node zero
2018-06-25 20:33:16.099100: I tensorflow/core/common_runtime/gpu/gpu_device.cc:1212] Found device 1 with properties: 
name: GeForce GTX 1080 Ti major: 6 minor: 1 memoryClockRate(GHz): 1.6325
pciBusID: 0000:02:00.0
totalMemory: 10.91GiB freeMemory: 10.75GiB
2018-06-25 20:33:16.099851: I tensorflow/core/common_runtime/gpu/gpu_device.cc:1227] Device peer to peer matrix
2018-06-25 20:33:16.099875: I tensorflow/core/common_runtime/gpu/gpu_device.cc:1233] DMA: 0 1 
2018-06-25 20:33:16.099882: I tensorflow/core/common_runtime/gpu/gpu_device.cc:1243] 0:   Y Y 
2018-06-25 20:33:16.099886: I tensorflow/core/common_runtime/gpu/gpu_device.cc:1243] 1:   Y Y 
2018-06-25 20:33:16.099892: I tensorflow/core/common_runtime/gpu/gpu_device.cc:1312] Adding visible gpu devices: 0, 1
2018-06-25 20:33:16.452425: I tensorflow/core/common_runtime/gpu/gpu_device.cc:993] Creating TensorFlow device (/job:localhost/replica:0/task:0/device:GPU:0 with 10346 MB memory) -> physical GPU (device: 0, name: GeForce GTX 1080 Ti, pci bus id: 0000:01:00.0, compute capability: 6.1)
2018-06-25 20:33:16.453236: I tensorflow/core/common_runtime/gpu/gpu_device.cc:993] Creating TensorFlow device (/job:localhost/replica:0/task:0/device:GPU:1 with 10407 MB memory) -> physical GPU (device: 1, name: GeForce GTX 1080 Ti, pci bus id: 0000:02:00.0, compute capability: 6.1)
2018-06-25 20:33:53.523552: I tensorflow/core/common_runtime/gpu/gpu_device.cc:1312] Adding visible gpu devices: 0, 1
2018-06-25 20:33:53.523805: I tensorflow/core/common_runtime/gpu/gpu_device.cc:993] Creating TensorFlow device (/job:localhost/replica:0/task:0/device:GPU:0 with 10344 MB memory) -> physical GPU (device: 0, name: GeForce GTX 1080 Ti, pci bus id: 0000:01:00.0, compute capability: 6.1)
2018-06-25 20:33:53.524059: I tensorflow/core/common_runtime/gpu/gpu_device.cc:993] Creating TensorFlow device (/job:localhost/replica:0/task:0/device:GPU:1 with 10405 MB memory) -> physical GPU (device: 1, name: GeForce GTX 1080 Ti, pci bus id: 0000:02:00.0, compute capability: 6.1)
WARNING:tensorflow:From train.py:156: softmax_cross_entropy_with_logits (from tensorflow.python.ops.nn_ops) is deprecated and will be removed in a future version.
Instructions for updating:

Future major versions of TensorFlow will allow gradients to flow
into the labels input on backprop by default.

See tf.nn.softmax_cross_entropy_with_logits_v2.

INFO:tensorflow:Training from step: 1 
Total number of Parameters:  949862
Traceback (most recent call last):
  File "/home/vampsj/git/deep-venv/lib/python3.5/site-packages/tensorflow/python/client/session.py", line 1361, in _do_call
    return fn(*args)
  File "/home/vampsj/git/deep-venv/lib/python3.5/site-packages/tensorflow/python/client/session.py", line 1340, in _run_fn
    target_list, status, run_metadata)
  File "/home/vampsj/git/deep-venv/lib/python3.5/site-packages/tensorflow/python/framework/errors_impl.py", line 516, in __exit__
    c_api.TF_GetCode(self.status.status))
tensorflow.python.framework.errors_impl.InvalidArgumentError: Input to reshape is a tensor with 167400 values, but the requested shape requires a multiple of 6138
	 [[Node: Reshape_1 = Reshape[T=DT_FLOAT, Tshape=DT_INT32, _device="/job:localhost/replica:0/task:0/device:GPU:0"](dropout/mul, Reshape_1/shape)]]

During handling of the above exception, another exception occurred:

Traceback (most recent call last):
  File "train.py", line 456, in <module>
    tf.app.run(main=main, argv=[sys.argv[0]] + unparsed)
  File "/home/vampsj/git/deep-venv/lib/python3.5/site-packages/tensorflow/python/platform/app.py", line 126, in run
    _sys.exit(main(argv))
  File "train.py", line 237, in main
    dropout_prob: 1.0
  File "/home/vampsj/git/deep-venv/lib/python3.5/site-packages/tensorflow/python/client/session.py", line 905, in run
    run_metadata_ptr)
  File "/home/vampsj/git/deep-venv/lib/python3.5/site-packages/tensorflow/python/client/session.py", line 1137, in _run
    feed_dict_tensor, options, run_metadata)
  File "/home/vampsj/git/deep-venv/lib/python3.5/site-packages/tensorflow/python/client/session.py", line 1355, in _do_run
    options, run_metadata)
  File "/home/vampsj/git/deep-venv/lib/python3.5/site-packages/tensorflow/python/client/session.py", line 1374, in _do_call
    raise type(e)(node_def, op, message)
tensorflow.python.framework.errors_impl.InvalidArgumentError: Input to reshape is a tensor with 167400 values, but the requested shape requires a multiple of 6138
	 [[Node: Reshape_1 = Reshape[T=DT_FLOAT, Tshape=DT_INT32, _device="/job:localhost/replica:0/task:0/device:GPU:0"](dropout/mul, Reshape_1/shape)]]

Caused by op 'Reshape_1', defined at:
  File "train.py", line 456, in <module>
    tf.app.run(main=main, argv=[sys.argv[0]] + unparsed)
  File "/home/vampsj/git/deep-venv/lib/python3.5/site-packages/tensorflow/python/platform/app.py", line 126, in run
    _sys.exit(main(argv))
  File "train.py", line 139, in main
    is_training=True)
  File "/home/vampsj/git/MyKWS/models.py", line 120, in create_model
    is_training)
  File "/home/vampsj/git/MyKWS/models.py", line 402, in create_low_latency_conv_model
    [-1, first_conv_element_count])
  File "/home/vampsj/git/deep-venv/lib/python3.5/site-packages/tensorflow/python/ops/gen_array_ops.py", line 3903, in reshape
    "Reshape", tensor=tensor, shape=shape, name=name)
  File "/home/vampsj/git/deep-venv/lib/python3.5/site-packages/tensorflow/python/framework/op_def_library.py", line 787, in _apply_op_helper
    op_def=op_def)
  File "/home/vampsj/git/deep-venv/lib/python3.5/site-packages/tensorflow/python/framework/ops.py", line 3271, in create_op
    op_def=op_def)
  File "/home/vampsj/git/deep-venv/lib/python3.5/site-packages/tensorflow/python/framework/ops.py", line 1650, in __init__
    self._traceback = self._graph._extract_stack()  # pylint: disable=protected-access

InvalidArgumentError (see above for traceback): Input to reshape is a tensor with 167400 values, but the requested shape requires a multiple of 6138
	 [[Node: Reshape_1 = Reshape[T=DT_FLOAT, Tshape=DT_INT32, _device="/job:localhost/replica:0/task:0/device:GPU:0"](dropout/mul, Reshape_1/shape)]]

